Workbook

Sheet Configuracion
A1: Clave | B1: HojaDestino | C1: CeldaDestino | D1: Tipo | E1: Formato
A2: Denominacion | B2: EstadoSituacionFin | C2: A1:AA4 | D2: Texto
A3: Denominacion | B3: BalanceGeneral | C3: A1:AA4 | D3: Texto
A4: Denominacion | B4: EstadoActividades | C4: A1:AA4 | D4: Texto
A5: Denominacion | B5: EstadoResultados | C5: A1:AA4 | D5: Texto
A6: Logo | B6: EstadoSituacionFin | C6: AB1:AF4 | D6: Imagen
A7: Logo | B7: BalanceGeneral | C7: AB1:AF4 | D7: Imagen
A8: Logo | B8: EstadoActividades | C8: AB1:AF4 | D8: Imagen
A9: Logo | B9: EstadoResultados | C9: AB1:AF4 | D9: Imagen
A10: FechaInicio | B10: EstadoSituacionFin | C10: C9:P9 | D10: Número | E10: Fecha
A11: FechaInicio | B11: BalanceGeneral | C11: C9:P9 | D11: Número | E11: Fecha
A12: FechaInicio | B12: EstadoActividades | C12: C8:P8 | D12: Número | E12: Fecha
A13: FechaInicio | B13: EstadoResultados | C13: C8:P8 | D13: Número | E13: Fecha
A14: FechaFin | B14: EstadoSituacionFin | C14: S9:AF9 | D14: Número | E14: Fecha
A15: FechaFin | B15: BalanceGeneral | C15: S9:AF9 | D15: Número | E15: Fecha
A16: FechaFin | B16: EstadoActividades | C16: S8:AF8 | D16: Número | E16: Fecha
A17: FechaFin | B17: EstadoResultados | C17: S8:AF8 | D17: Número | E17: Fecha
A18: Creador | B18: EstadoSituacionFin | C18: A35:J35 | D18: Texto
A19: Creador | B19: BalanceGeneral | C19: A35:J35 | D19: Texto
A20: Creador | B20: EstadoActividades | C20: A36:J36 | D20: Texto
A21: Creador | B21: EstadoResultados | C21: A36:J36 | D21: Texto
A22: CargoCreador | B22: EstadoSituacionFin | C22: A36:J36 | D22: Texto
A23: CargoCreador | B23: BalanceGeneral | C23: A36:J36 | D23: Texto
A24: CargoCreador | B24: EstadoActividades | C24: A37:J37 | D24: Texto
A25: CargoCreador | B25: EstadoResultados | C25: A37:J37 | D25: Texto
A26: Supervisor1 | B26: EstadoSituacionFin | C26: A42:J42 | D26: Texto
A27: Supervisor1 | B27: BalanceGeneral | C27: A42:J42 | D27: Texto
A28: Supervisor1 | B28: EstadoActividades | C28: A43:J43 | D28: Texto
A29: Supervisor1 | B29: EstadoResultados | C29: A43:J43 | D29: Texto
... A49: RFC | B49: EstadoResultados | C49: A46:AF46 | D49: Texto

Sheet Mapeo_Fiscal
A1: Codigo | B1: Nombre cuenta base | C1: Tipo_operacion | D1: IVA tasa | E1: Aplica IVA | F1: ISR retencion | G1: IVA retencion | H1: Codigo_destino_IVA | I1: Codigo_destino_ISR | J1: Codigo_destino_IVA_retencion | K1: CFDI tipo | L1: Comentario | M1: clave_prodserv_sat | N1: unidad_sat_default | O1: uso_cfdi_default | P1: es_donativo | Q1: requiere_complemento | R1: regimen_emisor_sugerido | S1: tipo_de_cliente_pref | T1: metodo_pago_default | U1: forma_pago_default | V1: generar_folio_auto
A2: 4101 | B2: Ventas nacionales | C2: Ingreso | D2: 16 | E2: Sí | F2: 0 | G2: 0 | H2: 2080 | I2: — | J2: — | K2: I | L2: Venta con IVA general | M2: 01010101 | N2: ACT | O2: G03 | P2: False | R2: Resico-PM | S2: Cualquiera | T2: PUE | U2: 3 | V2: True
A3: 4202 | B3: Honorarios | C3: Egreso | D3: 16 | E3: Sí | F3: 10 | G3: 10.667 | H3: 1180 | I3: 2160 | J3: 2170 | K3: E | L3: Retenciones aplican si proveedor PF | M3: 84111506 | N3: H87 | O3: G03 | P3: False | R3: Resico-PF | S3: PersonaFisica | T3: PUE | U3: 3 | V3: True
A4: 5202 | B4: Honorarios asimilados | C4: Egreso | D4: 0 | E4: No | F4: 10 | G4: 0 | H4: — | I4: 2160 | J4: — | K4: E | L4: Asimilados sin IVA, solo ISR | M4: 84111506 | N4: H87 | O4: G03 | P4: False | R4: Resico-PF | S4: PersonaFisica | T4: PUE | U4: 3 | V4: True
A5: 5101 | B5: Compra de insumos | C5: Egreso | D5: 16 | E5: Sí | F5: 0 | G5: 0 | H5: 1180 | I5: — | J5: — | K5: E | L5: Compra con IVA acreditable | M5: 01010101 | N5: PIEZA | O5: G03 | P5: False | R5: Resico-PM | S5: Cualquiera | T5: PUE | U5: 3 | V5: True
A6: 6101 | B6: Donativos recibidos | C6: Ingreso | D6: 0 | E6: No | F6: 0 | G6: 0 | H6: — | I6: — | J6: — | K6: I | L6: Complemento Donatarias | M6: 80141600 | N6: ACT | O6: D03 | P6: True | Q6: Donatarias | R6: AC | S6: Cualquiera | T6: PUE | U6: 3 | V6: True
A7: 4302 | B7: Intereses bancarios | C7: Ingreso | D7: 0 | E7: No | F7: 1.25 | G7: 0 | H7: — | I7: 2180 | J7: — | K7: I | L7: ISR retenido por banco | M7: 84111506 | N7: ACT | O7: G03 | P7: False | R7: Resico-PM | S7: Cualquiera | T7: PUE | U7: 3 | V7: True
A8: 5203 | B8: Cuotas IMSS e impuestos | C8: Egreso | D8: 0 | E8: No | F8: 0 | G8: 0 | H8: — | I8: — | J8: — | K8: E | L8: Pago de obligaciones laborales | M8: 84111506 | N8: ACT | O8: G03 | P8: False | R8: Resico-PM | S8: Cualquiera | T8: PUE | U8: 3 | V8: True
A9: 5304 | B9: Impuestos locales | C9: Egreso | D9: 0 | E9: No | F9: 0 | G9: 0 | H9: — | I9: — | J9: — | K9: E | L9: Derechos o contribuciones locales | M9: 80141600 | N9: ACT | O9: G03 | P9: False | R9: Resico-PM | S9: Cualquiera | T9: PUE | U9: 3 | V9: True
A10: 4203 | B10: Servicios de capacitación | C10: Ingreso | D10: 16 | E10: Sí | F10: 0 | G10: 0 | H10: 2080 | I10: — | J10: — | K10: I | L10: Curso, taller o asesoría | M10: 84111506 | N10: H87 | O10: G03 | P10: False | R10: AC | S10: Cualquiera | T10: PUE | U10: 3 | V10: True
A11: 4204 | B11: Eventos y ferias | C11: Ingreso | D11: 16 | E11: Sí | F11: 0 | G11: 0 | H11: 2080 | I11: — | J11: — | K11: I | L11: Venta de entradas, stands o participación | M11: 84111506 | N11: H87 | O11: G03 | P11: False | R11: AC | S11: Cualquiera | T11: PUE | U11: 3 | V11: True
A12: 5102 | B12: Servicios básicos | C12: Egreso | D12: 16 | E12: Sí | F12: 0 | G12: 0 | H12: 1180 | I12: — | J12: — | K12: E | L12: Luz, agua, gas | M12: 01010101 | N12: ACT | O12: G03 | P12: False | R12: Resico-PM | S12: Cualquiera | T12: PUE | U12: 3 | V12: True
A13: 5103 | B13: Arrendamientos | C13: Egreso | D13: 16 | E13: Sí | F13: 0 | G13: 0 | H13: 1180 | I13: — | J13: — | K13: E | L13: Renta de inmuebles y equipos | M13: 80131500 | N13: ACT | O13: G03 | P13: False | R13: Resico-PM | S13: Cualquiera | T13: PUE | U13: 3 | V13: True
A14: 5104 | B14: Mantenimiento y reparaciones | C14: Egreso | D14: 16 | E14: Sí | F14: 0 | G14: 0 | H14: 1180 | I14: — | J14: — | K14: E | L14: Reparación y conservación de activos | M14: 01010101 | N14: PIEZA | O14: G03 | P14: False | R14: Resico-PM | S14: Cualquiera | T14: PUE | U14: 3 | V14: True
A15: 5105 | B15: Transporte y mensajería | C15: Egreso | D15: 16 | E15: Sí | F15: 0 | G15: 0 | H15: 1180 | I15: — | J15: — | K15: E | L15: Fletes, envíos, paquetería | M15: 01010101 | N15: PIEZA | O15: G03 | P15: False | R15: Resico-PM | S15: Cualquiera | T15: PUE | U15: 3 | V15: True
A16: 5201 | B16: Sueldos | C16: Egreso | D16: 0 | E16: No | F16: 10 | G16: 0 | H16: — | I16: 2160 | J16: — | K16: E | L16: Nómina personal operativo | M16: 84111506 | N16: ACT | O16: G03 | P16: False | Q16: Nómina | R16: Resico-PM | S16: Cualquiera | T16: PUE | U16: 3 | V16: True
A17: 5401 | B17: Becas y apoyos sociales | C17: Egreso | D17: 0 | E17: No | F17: 0 | G17: 0 | H17: — | I17: — | J17: — | K17: E | L17: Apoyos económicos o materiales a beneficiarios | M17: 80141600 | N17: ACT | O17: G03 | P17: False | R17: AC | S17: Cualquiera | T17: PUE | U17: 3 | V17: True
A18: 5402 | B18: Capacitación de aprendices | C18: Egreso | D18: 0 | E18: No | F18: 0 | G18: 0 | H18: — | I18: — | J18: — | K18: E | L18: Formación técnica o laboral | M18: 84111506 | N18: ACT | O18: G03 | P18: False | R18: AC | S18: Cualquiera | T18: PUE | U18: 3 | V18: True
A19: 5403 | B19: Material para talleres productivos | C19: Egreso | D19: 16 | E19: Sí | F19: 0 | G19: 0 | H19: 1180 | I19: — | J19: — | K19: E | L19: Suministros para talleres de confección | M19: 01010101 | N19: PIEZA | O19: G03 | P19: False | R19: AC | S19: Cualquiera | T19: PUE | U19: 3 | V19: True
A20: 5404 | B20: Publicidad y difusión institucional | C20: Egreso | D20: 16 | E20: Sí | F20: 0 | G20: 0 | H20: 1180 | I20: — | J20: — | K20: E | L20: Promoción de actividades con causa | M20: 01010101 | N20: PIEZA | O20: G03 | P20: False | R20: AC | S20: Cualquiera | T20: PUE | U20: 3 | V20: True
A21: 5405 | B21: Beneficios al personal operativo | C21: Egreso | D21: 0 | E21: No | F21: 0 | G21: 0 | H21: — | I21: — | J21: — | K21: E | L21: Apoyos en especie o servicios | M21: 80141600 | N21: ACT | O21: G03 | P21: False | R21: AC | S21: Cualquiera | T21: PUE | U21: 3 | V21: True
A22: 4301 | B22: Recuperación de gastos | C22: Ingreso | D22: 0 | E22: No | F22: 0 | G22: 0 | H22: — | I22: — | J22: — | K22: I | L22: Reintegros o reembolsos | M22: 01010101 | N22: ACT | O22: G03 | P22: False | R22: Resico-PM | S22: Cualquiera | T22: PUE | U22: 3 | V22: True
A23: 4201 | B23: Venta de productos elaborados | C23: Ingreso | D23: 16 | E23: Sí | F23: 0 | G23: 0 | H23: 2080 | I23: — | J23: — | K23: I | L23: Productos confeccionados o artesanales | M23: 01010101 | N23: PIEZA | O23: G03 | P23: False | R23: AC | S23: Cualquiera | T23: PUE | U23: 3 | V23: True
A24: 4303 | B24: Otros ingresos | C24: Ingreso | D24: 16 | E24: Sí | F24: 0 | G24: 0 | H24: 2080 | I24: — | J24: — | K24: I | L24: Ingresos varios | M24: 01010101 | N24: ACT | O24: G03 | P24: False | R24: AC | S24: Cualquiera | T24: PUE | U24: 3 | V24: True
A25: 5106 | B25: Gastos varios | C25: Egreso | D25: 16 | E25: Sí | F25: 0 | G25: 0 | H25: 1180 | I25: — | J25: — | K25: E | L25: Gastos operativos no clasificados | M25: 01010101 | N25: PIEZA | O25: G03 | P25: False | R25: AC | S25: Cualquiera | T25: PUE | U25: 3 | V25: True
A26: 5204 | B26: Prestaciones al personal | C26: Egreso | D26: 0 | E26: No | F26: 0 | G26: 0 | H26: — | I26: — | J26: — | K26: E | L26: Beneficios legales o contractuales | M26: 84111506 | N26: ACT | O26: G03 | P26: False | R26: Resico-PM | S26: Cualquiera | T26: PUE | U26: 3 | V26: True

Sheet Catalogo
A1: Codigo | B1: Nombre_OSC | C1: Nombre_Comercial | D1: Tipo_cuenta | E1: Subtipo | F1: Naturaleza | G1: Descripción/uso | H1: Reporte_OSC | I1: Reporte_Comercial
A2: 1101 | B2: Bancos | C2: Bancos | D2: Activo | E2: Circulante | F2: Deudora | G2: Dinero en cuentas bancarias de la Asociación | H2: Estado de situación financiera | I2: Balance General
A3: 1102 | B3: Caja chica | C3: Caja chica | D3: Activo | E3: Circulante | F3: Deudora | G3: Efectivo disponible para gastos menores | H3: Estado de situación financiera | I3: Balance General
A4: 1103 | B4: Cuentas por cobrar | C4: Clientes | D4: Activo | E4: Circulante | F4: Deudora | G4: Importes pendientes de cobro por ventas o servicios | H4: Estado de situación financiera | I4: Balance General
A5: 1104 | B5: Inventarios de materiales | C5: Inventario | D5: Activo | E5: Circulante | F5: Deudora | G5: Materiales y suministros disponibles para operación | H5: Estado de situación financiera | I5: Balance General
A6: 1105 | B6: Anticipos a proveedores | C6: Anticipos a proveedores | D6: Activo | E6: Circulante | F6: Deudora | G6: Pagos adelantados a proveedores | H6: Estado de situación financiera | I6: Balance General
A7: 1106 | B7: Donativos en especie por aplicar | C7: Mercancía en tránsito/otros activos circulantes | D7: Activo | E7: Circulante | F7: Deudora | G7: Bienes recibidos como donativos pendientes de asignación | H7: Estado de situación financiera | I7: Balance General
A8: 1201 | B8: Mobiliario y equipo | C8: Mobiliario y equipo de oficina | D8: Activo | E8: No circulante | F8: Deudora | G8: Mesas, sillas y otros bienes de oficina | H8: Estado de situación financiera | I8: Balance General
A9: 1202 | B9: Equipo de cómputo | C9: Equipo de cómputo | D9: Activo | E9: No circulante | F9: Deudora | G9: Computadoras y accesorios | H9: Estado de situación financiera | I9: Balance General
A10: 1203 | B10: Maquinaria y herramientas | C10: Maquinaria y herramientas | D10: Activo | E10: No circulante | F10: Deudora | G10: Equipos de talleres y producción | H10: Estado de situación financiera | I10: Balance General
A11: 1204 | B11: Terrenos y edificios | C11: Terrenos y edificios | D11: Activo | E11: No circulante | F11: Deudora | G11: Inmuebles propiedad de la Asociación | H11: Estado de situación financiera | I11: Balance General
A12: 1205 | B12: Depreciación acumulada | C12: Depreciación acumulada | D12: Activo | E12: No circulante | F12: Acreedora | G12: Depreciación total acumulada de los activos fijos | H12: Estado de situación financiera | I12: Balance General
A13: 2101 | B13: Proveedores | C13: Proveedores | D13: Pasivo | E13: Corto plazo | F13: Acreedora | G13: Cuentas pendientes de pago a proveedores | H13: Estado de situación financiera | I13: Balance General
... A18: 2202 | B18: Otros pasivos a largo plazo | C18: Otros pasivos a largo plazo | D18: Pasivo | E18: Largo plazo | F18: Acreedora | G18: Compromisos financieros no corrientes | H18: Estado de situación financiera | I18: Balance General
A19: 3101 | B19: Aportaciones de asociados | C19: Capital social | D19: Patrimonio | F19: Acreedora | G19: Aportaciones de miembros fundadores o asociados | H19: Estado de situación financiera | I19: Balance General
A20: 3102 | B20: Donativos acumulados | C20: Utilidades retenidas | D20: Patrimonio | F20: Acreedora | G20: Donativos recibidos acumulados de ejercicios anteriores | H20: Estado de situación financiera | I20: Balance General
A21: 3103 | B21: Resultados del ejercicio | C21: Utilidad o pérdida del ejercicio | D21: Patrimonio | F21: Acreedora | G21: Resultado (superávit o déficit) del ejercicio actual | H21: Estado de situación financiera | I21: Balance General
A22: 3104 | B22: Reservas patrimoniales | C22: Reservas de capital | D22: Patrimonio | F22: Acreedora | G22: Recursos destinados a fines específicos o contingencias | H22: Estado de situación financiera | I22: Balance General
A23: 4101 | B23: Donativos en efectivo | C23: Ventas al contado | D23: Ingreso | E23: Donativos | F23: Acreedora | G23: Donaciones recibidas en efectivo | H23: Estado de actividades | I23: Estado de resultados
A24: 4102 | B24: Donativos en especie | C24: Ventas en especie | D24: Ingreso | E24: Donativos | F24: Acreedora | G24: Bienes materiales donados | H24: Estado de actividades | I24: Estado de resultados
A25: 4103 | B25: Donativos recurrentes | C25: Ventas recurrentes | D25: Ingreso | E25: Donativos | F25: Acreedora | G25: Aportaciones periódicas o programadas | H25: Estado de actividades | I25: Estado de resultados
A26: 4104 | B26: Donativos institucionales | C26: Ingresos por convenio o contratos | D26: Ingreso | E26: Donativos | F26: Acreedora | G26: Donativos de fundaciones, empresas o gobiernos | H26: Estado de actividades | I26: Estado de resultados
A27: 4201 | B27: Ventas de productos elaborados | C27: Venta de productos elaborados | D27: Ingreso | E27: Actividades con causa | F27: Acreedora | G27: Ingresos por productos confeccionados o artesanales | H27: Estado de actividades | I27: Estado de resultados
A28: 4202 | B28: Servicios de capacitación | C28: Prestación de servicios | D28: Ingreso | E28: Actividades con causa | F28: Acreedora | G28: Cursos, talleres o asesorías | H28: Estado de actividades | I28: Estado de resultados
A29: 4203 | B29: Ingresos por eventos o ferias | C29: Ingresos por eventos | D29: Ingreso | E29: Actividades con causa | F29: Acreedora | G29: Recursos generados en eventos | H29: Estado de actividades | I29: Estado de resultados
A30: 4301 | B30: Recuperación de gastos | C30: Otros ingresos | D30: Ingreso | E30: Otros | F30: Acreedora | G30: Reintegros o reembolsos de gastos | H30: Estado de actividades | I30: Estado de resultados
A31: 4302 | B31: Intereses bancarios | C31: Intereses ganados | D31: Ingreso | E31: Otros | F31: Acreedora | G31: Intereses generados por cuentas bancarias | H31: Estado de actividades | I31: Estado de resultados
A32: 5101 | B32: Materiales y suministros | C32: Materiales y suministros | D32: Gasto | E32: Operación | F32: Deudora | G32: Compra de materiales y suministros generales | H32: Estado de actividades | I32: Estado de resultados
A33: 5102 | B33: Servicios básicos | C33: Servicios básicos | D33: Gasto | E33: Operación | F33: Deudora | G33: Servicios básicos de operación | H33: Estado de actividades | I33: Estado de resultados
A34: 5103 | B34: Arrendamientos | C34: Arrendamientos | D34: Gasto | E34: Operación | F34: Deudora | G34: Rentas de inmuebles o equipo | H34: Estado de actividades | I34: Estado de resultados
... A62: 5304 | B62: Impuestos locales y derechos | C62: Impuestos locales | D62: Gasto | E62: Impuesto | F62: Deudora | G62: Contribuciones estatales o municipales (por ejemplo, nómina o predial). | H62: Estado de actividades | I62: Estado de resultados

Sheet ParametrosFiscales
A1: Parámetro | B1: Valor | C1: Unidad / Nota | D1: Comentario
A2: IVA_general | B2: 16 | C2: % | D2: Tasa estándar de IVA para operaciones gravadas
A3: IVA_cero | B3: 0 | C3: % | D3: Operaciones exentas de IVA
A4: IVA_exento | B4: Exento | C4: — | D4: Se usa para servicios o productos exentos
A5: ISR_retencion_pf | B5: 10 | C5: % | D5: Retención de ISR sobre pagos a Personas Físicas
A6: ISR_retencion_asimilados | B6: 1.25 | C6: % | D6: Retención ISR para honorarios asimilados
A7: IVA_retencion_general | B7: 66.6667 | C7: % del IVA | D7: Retención sobre IVA trasladado (equivalente a 2/3)
A8: IVA_retencion_sobre | B8: iva | C8: "iva" / "subtotal" | D8: Define base de cálculo de retención de IVA
A9: Metodo_pago_default | B9: PUE | C9: PPD opcional | D9: PUE: pago en una sola exhibición; PPD: pago en parcialidades
A10: Forma_pago_efectivo | B10: 1 | C10: CFDI | D10: Pago en efectivo
A11: Forma_pago_transferencia | B11: 3 | C11: CFDI | D11: Pago por transferencia bancaria
A12: Complemento_donatarias_activo | B12: True | C12: Boolean | D12: Se activa para operaciones marcadas como donativo
A13: Complemento_nomina_activo | B13: True | C13: Boolean | D13: Para CFDI de nómina
A14: Complemento_arrendamiento_activo | B14: False | C14: Boolean | D14: Para CFDI de arrendamiento (si aplica)
A15: Regimen_Resico_PF | B15: Resico-PF | C15: String | D15: Para contribuyentes personas físicas en régimen simplificado
A16: Regimen_Resico_PM | B16: Resico-PM | C16: String | D16: Para contribuyentes personas morales en régimen simplificado
A17: Regimen_AC | B17: AC | C17: String | D17: Asociaciones civiles y donatarias
A18: Regimen_Moral_ISR | B18: Moral-ISR | C18: String | D18: Personas morales con régimen normal
A19: Tipo_cliente_pref_PF | B19: PersonaFisica | C19: Enum | D19: Para validación de CFDI receptor
A20: Tipo_cliente_pref_PM | B20: PersonaMoral | C20: Enum | D20: Para validación de CFDI receptor
A21: IVA_acreditable_cuenta | B21: 1180 | C21: Código de cuenta contable | D21: Cuenta destino para IVA acreditable
A22: IVA_trasladado_cuenta | B22: 2080 | C22: Código de cuenta contable | D22: Cuenta destino para IVA trasladado
A23: ISR_retenido_cuenta | B23: 2160 | C23: Código de cuenta contable | D23: Cuenta destino para ISR retenido
A24: IVA_retenido_cuenta | B24: 2170 | C24: Código de cuenta contable | D24: Cuenta destino para IVA retenido
A25: Dias_pago_maximo | B25: 30 | C25: días | D25: Para validaciones de PPD (pago en parcialidades)
A26: Uso_cfdi_default_gastos | B26: G03 | C26: Clave SAT | D26: Uso de CFDI recomendado para gastos generales
A27: Uso_cfdi_default_donativos | B27: D03 | C27: Clave SAT | D27: Uso de CFDI recomendado para donativos
A28: Unidad_default | B28: ACT | C28: Clave SAT | D28: Unidad de medida estándar (actividad)
A29: Unidad_default_pieza | B29: PIEZA | C29: Clave SAT | D29: Unidad para productos físicos
A30: IVA_0_condicion | B30: True | C30: Boolean | D30: Indica que ciertas cuentas tienen IVA 0 o exento
A31: Retencion_ISR_condicion | B31: True | C31: Boolean | D31: Define si la cuenta aplica retención de ISR
A32: Retencion_IVA_condicion | B32: True | C32: Boolean | D32: Define si la cuenta aplica retención de IVA

Sheet Mapeo_Polizas
A1: Tipo_Poliza | B1: Tipo_Cuenta | C1: Naturaleza | D1: Rol | E1: Incluir | F1: Comentario
A2: Ingresos | B2: Activo | C2: Deudora | D2: Cargo | E2: TRUE | F2: Entradas de efectivo o bancos
A3: Ingresos | B3: Ingreso | C3: Acreedora | D3: Abono | E3: TRUE | F3: Reconocimiento de ingreso
A4: Ingresos | B4: Pasivo | C4: Acreedora | D4: Abono | E4: TRUE | F4: ISR o IVA trasladado pendiente
A5: Egresos | B5: Activo | C5: Deudora | D5: Abono | E5: TRUE | F5: Salida de efectivo o bancos
A6: Egresos | B6: Gasto | C6: Deudora | D6: Cargo | E6: TRUE | F6: Reconocimiento del gasto
A7: Egresos | B7: Pasivo | C7: Acreedora | D7: Abono | E7: TRUE | F7: IVA acreditable o retenciones
A8: Diario | B8: * | C8: * | D8: Ambos | E8: TRUE | F8: Movimientos internos entre cuentas

Sheet Movimientos
A1: Fecha | B1: Codigo | C1: Cuenta | D1: Cargo | E1: Abono | F1: Tipo_Poliza | G1: Descripcion | H1: Documento soporte | I1: Folio | J1: Denominacion | K1: R.F.C. | L1: Concepto | M1: Cantidad | N1: Unidad | O1: Valor_unitario | P1: Importe total | Q1: IVA | R1: ISR retencion | S1: IVA retencion | T1: Tipo_operacion | U1: Metodo de pago

Sheet LibroMayor
A1: Código | B1: Nombre de la cuenta | C1: Cargo | D1: Abono | E1: Saldo
A2: 1101 | B2: Bancos | C2: =SUMIF(Movimientos!B:B,LibroMayor!$A2,Movimientos!D:D) -> 0 | D2: =SUMIF(Movimientos!B:B,LibroMayor!$A2,Movimientos!E:E) -> 0 | E2: =C2-D2 -> 0
A3: 1102 | B3: Caja chica | C3: =SUMIF(Movimientos!B:B,LibroMayor!$A3,Movimientos!D:D) -> 0 | D3: =SUMIF(Movimientos!B:B,LibroMayor!$A3,Movimientos!E:E) -> 0 | E3: =C3-D3 -> 0
A4: 1103 | B4: Cuentas por cobrar | C4: =SUMIF(Movimientos!B:B,LibroMayor!$A4,Movimientos!D:D) -> 0 | D4: =SUMIF(Movimientos!B:B,LibroMayor!$A4,Movimientos!E:E) -> 0 | E4: =C4-D4 -> 0
A5: 1104 | B5: Inventarios de materiales | C5: =SUMIF(Movimientos!B:B,LibroMayor!$A5,Movimientos!D:D) -> 0 | D5: =SUMIF(Movimientos!B:B,LibroMayor!$A5,Movimientos!E:E) -> 0 | E5: =C5-D5 -> 0
A6: 1105 | B6: Anticipos a proveedores | C6: =SUMIF(Movimientos!B:B,LibroMayor!$A6,Movimientos!D:D) -> 0 | D6: =SUMIF(Movimientos!B:B,LibroMayor!$A6,Movimientos!E:E) -> 0 | E6: =C6-D6 -> 0
A7: 1106 | B7: Donativos en especie por aplicar | C7: =SUMIF(Movimientos!B:B,LibroMayor!$A7,Movimientos!D:D) -> 0 | D7: =SUMIF(Movimientos!B:B,LibroMayor!$A7,Movimientos!E:E) -> 0 | E7: =C7-D7 -> 0
A8: 1201 | B8: Mobiliario y equipo | C8: =SUMIF(Movimientos!B:B,LibroMayor!$A8,Movimientos!D:D) -> 0 | D8: =SUMIF(Movimientos!B:B,LibroMayor!$A8,Movimientos!E:E) -> 0 | E8: =C8-D8 -> 0
A9: 1202 | B9: Equipo de cómputo | C9: =SUMIF(Movimientos!B:B,LibroMayor!$A9,Movimientos!D:D) -> 0 | D9: =SUMIF(Movimientos!B:B,LibroMayor!$A9,Movimientos!E:E) -> 0 | E9: =C9-D9 -> 0
A10: 1203 | B10: Maquinaria y herramientas | C10: =SUMIF(Movimientos!B:B,LibroMayor!$A10,Movimientos!D:D) -> 0 | D10: =SUMIF(Movimientos!B:B,LibroMayor!$A10,Movimientos!E:E) -> 0 | E10: =C10-D10 -> 0
A11: 1204 | B11: Terrenos y edificios | C11: =SUMIF(Movimientos!B:B,LibroMayor!$A11,Movimientos!D:D) -> 0 | D11: =SUMIF(Movimientos!B:B,LibroMayor!$A11,Movimientos!E:E) -> 0 | E11: =C11-D11 -> 0
A12: 1205 | B12: Depreciación acumulada | C12: =SUMIF(Movimientos!B:B,LibroMayor!$A12,Movimientos!D:D) -> 0 | D12: =SUMIF(Movimientos!B:B,LibroMayor!$A12,Movimientos!E:E) -> 0 | E12: =C12-D12 -> 0
A13: 2101 | B13: Proveedores | C13: =SUMIF(Movimientos!B:B,LibroMayor!$A13,Movimientos!D:D) -> 0 | D13: =SUMIF(Movimientos!B:B,LibroMayor!$A13,Movimientos!E:E) -> 0 | E13: =D13-C13 -> 0
A14: 2102 | B14: Acreedores diversos | C14: =SUMIF(Movimientos!B:B,LibroMayor!$A14,Movimientos!D:D) -> 0 | D14: =SUMIF(Movimientos!B:B,LibroMayor!$A14,Movimientos!E:E) -> 0 | E14: =D14-C14 -> 0
A15: 2103 | B15: Impuestos por pagar | C15: =SUMIF(Movimientos!B:B,LibroMayor!$A15,Movimientos!D:D) -> 0 | D15: =SUMIF(Movimientos!B:B,LibroMayor!$A15,Movimientos!E:E) -> 0 | E15: =D15-C15 -> 0
A16: 2104 | B16: Sueldos y prestaciones por pagar | C16: =SUMIF(Movimientos!B:B,LibroMayor!$A16,Movimientos!D:D) -> 0 | D16: =SUMIF(Movimientos!B:B,LibroMayor!$A16,Movimientos!E:E) -> 0 | E16: =D16-C16 -> 0
A17: 2201 | B17: Préstamos bancarios | C17: =SUMIF(Movimientos!B:B,LibroMayor!$A17,Movimientos!D:D) -> 0 | D17: =SUMIF(Movimientos!B:B,LibroMayor!$A17,Movimientos!E:E) -> 0 | E17: =D17-C17 -> 0
A18: 2202 | B18: Otros pasivos a largo plazo | C18: =SUMIF(Movimientos!B:B,LibroMayor!$A18,Movimientos!D:D) -> 0 | D18: =SUMIF(Movimientos!B:B,LibroMayor!$A18,Movimientos!E:E) -> 0 | E18: =D18-C18 -> 0
A19: 3101 | B19: Aportaciones de asociados | C19: =SUMIF(Movimientos!B:B,LibroMayor!$A19,Movimientos!D:D) -> 0 | D19: =SUMIF(Movimientos!B:B,LibroMayor!$A19,Movimientos!E:E) -> 0 | E19: =D19-C19 -> 0
A20: 3102 | B20: Donativos acumulados | C20: =SUMIF(Movimientos!B:B,LibroMayor!$A20,Movimientos!D:D) -> 0 | D20: =SUMIF(Movimientos!B:B,LibroMayor!$A20,Movimientos!E:E) -> 0 | E20: =D20-C20 -> 0
A21: 3103 | B21: Resultados del ejercicio | E21: =ReportesFinancieros!C72 -> 0
A22: 3104 | B22: Reservas patrimoniales | C22: =SUMIF(Movimientos!B:B,LibroMayor!$A22,Movimientos!D:D) -> 0 | D22: =SUMIF(Movimientos!B:B,LibroMayor!$A22,Movimientos!E:E) -> 0 | E22: =D22-C22 -> 0
A23: 4101 | B23: Donativos en efectivo | C23: =SUMIF(Movimientos!B:B,LibroMayor!$A23,Movimientos!D:D) -> 0 | D23: =SUMIF(Movimientos!B:B,LibroMayor!$A23,Movimientos!E:E) -> 0 | E23: =D23-C23 -> 0
A24: 4102 | B24: Donativos en especie | C24: =SUMIF(Movimientos!B:B,LibroMayor!$A24,Movimientos!D:D) -> 0 | D24: =SUMIF(Movimientos!B:B,LibroMayor!$A24,Movimientos!E:E) -> 0 | E24: =D24-C24 -> 0
A25: 4103 | B25: Donativos recurrentes | C25: =SUMIF(Movimientos!B:B,LibroMayor!$A25,Movimientos!D:D) -> 0 | D25: =SUMIF(Movimientos!B:B,LibroMayor!$A25,Movimientos!E:E) -> 0 | E25: =D25-C25 -> 0
A26: 4104 | B26: Donativos institucionales | C26: =SUMIF(Movimientos!B:B,LibroMayor!$A26,Movimientos!D:D) -> 0 | D26: =SUMIF(Movimientos!B:B,LibroMayor!$A26,Movimientos!E:E) -> 0 | E26: =D26-C26 -> 0
A27: 4201 | B27: Ventas de productos elaborados | C27: =SUMIF(Movimientos!B:B,LibroMayor!$A27,Movimientos!D:D) -> 0 | D27: =SUMIF(Movimientos!B:B,LibroMayor!$A27,Movimientos!E:E) -> 0 | E27: =D27-C27 -> 0
A28: 4202 | B28: Servicios de capacitación | C28: =SUMIF(Movimientos!B:B,LibroMayor!$A28,Movimientos!D:D) -> 0 | D28: =SUMIF(Movimientos!B:B,LibroMayor!$A28,Movimientos!E:E) -> 0 | E28: =D28-C28 -> 0
A29: 4203 | B29: Ingresos por eventos o ferias | C29: =SUMIF(Movimientos!B:B,LibroMayor!$A29,Movimientos!D:D) -> 0 | D29: =SUMIF(Movimientos!B:B,LibroMayor!$A29,Movimientos!E:E) -> 0 | E29: =D29-C29 -> 0
A30: 4301 | B30: Recuperación de gastos | C30: =SUMIF(Movimientos!B:B,LibroMayor!$A30,Movimientos!D:D) -> 0 | D30: =SUMIF(Movimientos!B:B,LibroMayor!$A30,Movimientos!E:E) -> 0 | E30: =D30-C30 -> 0
A31: 4302 | B31: Intereses bancarios | C31: =SUMIF(Movimientos!B:B,LibroMayor!$A31,Movimientos!D:D) -> 0 | D31: =SUMIF(Movimientos!B:B,LibroMayor!$A31,Movimientos!E:E) -> 0 | E31: =D31-C31 -> 0
A32: 5101 | B32: Materiales y suministros | C32: =SUMIF(Movimientos!B:B,LibroMayor!$A32,Movimientos!D:D) -> 0 | D32: =SUMIF(Movimientos!B:B,LibroMayor!$A32,Movimientos!E:E) -> 0 | E32: =C32-D32 -> 0
A33: 5102 | B33: Energía eléctrica, agua y teléfono | C33: =SUMIF(Movimientos!B:B,LibroMayor!$A33,Movimientos!D:D) -> 0 | D33: =SUMIF(Movimientos!B:B,LibroMayor!$A33,Movimientos!E:E) -> 0 | E33: =C33-D33 -> 0
A34: 5103 | B34: Arrendamientos | C34: =SUMIF(Movimientos!B:B,LibroMayor!$A34,Movimientos!D:D) -> 0 | D34: =SUMIF(Movimientos!B:B,LibroMayor!$A34,Movimientos!E:E) -> 0 | E34: =C34-D34 -> 0
A35: 5104 | B35: Mantenimiento y reparaciones | C35: =SUMIF(Movimientos!B:B,LibroMayor!$A35,Movimientos!D:D) -> 0 | D35: =SUMIF(Movimientos!B:B,LibroMayor!$A35,Movimientos!E:E) -> 0 | E35: =C35-D35 -> 0
A36: 5105 | B36: Transporte y mensajería | C36: =SUMIF(Movimientos!B:B,LibroMayor!$A36,Movimientos!D:D) -> 0 | D36: =SUMIF(Movimientos!B:B,LibroMayor!$A36,Movimientos!E:E) -> 0 | E36: =C36-D36 -> 0
A37: 5201 | B37: Sueldos | C37: =SUMIF(Movimientos!B:B,LibroMayor!$A37,Movimientos!D:D) -> 0 | D37: =SUMIF(Movimientos!B:B,LibroMayor!$A37,Movimientos!E:E) -> 0 | E37: =C37-D37 -> 0
A38: 5202 | B38: Honorarios asimilados | C38: =SUMIF(Movimientos!B:B,LibroMayor!$A38,Movimientos!D:D) -> 0 | D38: =SUMIF(Movimientos!B:B,LibroMayor!$A38,Movimientos!E:E) -> 0 | E38: =C38-D38 -> 0
A39: 5203 | B39: Cuotas IMSS e impuestos laborales | C39: =SUMIF(Movimientos!B:B,LibroMayor!$A39,Movimientos!D:D) -> 0 | D39: =SUMIF(Movimientos!B:B,LibroMayor!$A39,Movimientos!E:E) -> 0 | E39: =C39-D39 -> 0
A40: 5301 | B40: Papelería y útiles | C40: =SUMIF(Movimientos!B:B,LibroMayor!$A40,Movimientos!D:D) -> 0 | D40: =SUMIF(Movimientos!B:B,LibroMayor!$A40,Movimientos!E:E) -> 0 | E40: =C40-D40 -> 0
...

Sheet ReportesFinancieros
A1: Código | B1: Nombre de cuenta | C1: Saldo
A2: 1101 | B2: Bancos
A3: 1102 | B3: Caja chica
A4: 1103 | B4: Cuentas por cobrar
A5: 1104 | B5: Inventario de materiales
A6: 1105 | B6: Anticipos a proveedores
A7: 1106 | B7: Donativos en especie por aplicar
A8: 1180 | B8: IVA acreditable
A9: 1181 | B9: IVA acreditable no deducible
A10: 1182 | B10: IVA pendiente de acreditar
A11: 2180 | B11: ISR retenido por terceros
A12: 2181 | B12: IVA retenido por terceros
B13: Total Activo circulante | C13: =SUM(C2:C12) -> 0
A14: 1201 | B14: Mobiliario y equipo
A15: 1202 | B15: Equipo de cómputo
A16: 1203 | B16: Maquinaria y herramientas
A17: 1204 | B17: Terrenos y edificios
A18: 1205 | B18: (-) Depreciación acumulada
B19: Total de Activo no circulante | C19: =SUM(C14:C17)-C18 -> 0
B20: ACTIVO | C20: =C13+C19 -> 0
A21: 2101 | B21: Proveedores
A22: 2102 | B22: Acreedores diversos
A23: 2103 | B23: Impuestos por pagar
A24: 2104 | B24: Sueldos y prestaciones por pagar
A25: 2080 | B25: IVA trasladado
A26: 2081 | B26: IVA trasladado pendiente de cobro
A27: 2160 | B27: ISR retenido a terceros
A28: 2170 | B28: IVA retenido a terceros
A29: 5206 | B29: ISR por pagar
B30: Total Pasivo corto plazo | C30: =SUM(C21:C29) -> 0
A31: 2201 | B31: Préstamos bancarios
A32: 2202 | B32: Otros pasivos a largo plazo
B33: Total Pasivo largo plazo | C33: =SUM(C31:C32) -> 0
A34: 3101 | B34: Aportaciones de asociados
A35: 3102 | B35: Donativos acumulados
A36: 3103 | B36: Resultados del ejercicio
A37: 3104 | B37: Reservas patrimoniales
B38: Total patrimonio | C38: =SUM(C34:C37) -> 0
B39: PASIVO Y PATRIMONIO | C39: =C30+C33+C38 -> 0
A40: 4101 | B40: Donativos en efectivo
...
